Workbook

Sheet Cover
B6: PayPal Holdings, Inc. (PYPL)
B7: 3-Statement Financial Model & Investment Analysis
B8: Equity Research — Investment Recommendation
B11: Sector: | C11: Financial Technology / Digital Payments
B12: Exchange: | C12: NASDAQ: PYPL
B13: Fiscal Year End: | C13: December 31
B14: Currency: | C14: USD (values in millions unless noted)
B16: Analyst: | C16: Carlos — Investment Analysis Portfolio Project
B17: Date: | C17: February 2026
B18: Data Sources: | C18: SEC EDGAR 10-K Filings, yfinance, Company Reports
B20: Historical Period: | C20: FY2019 — FY2025 (7 years)
B21: Forecast Period: | C21: FY2026E — FY2028E (3 years)
B22: Scenarios: | C22: Base Case / Bull Case / Bear Case
B23: Valuation Method: | C23: Discounted Cash Flow (DCF) — FCFF
B27: RECOMMENDATION
B28: To be determined after model completion
B29: Target Price: $___ | Current Price: $___ | Upside: ___%
B32: MODEL NAVIGATION
B33: Cover | C33: This page — project overview
B34: Assumptions | C34: All forecast drivers and inputs (start here)
B35: Income Statement | C35: Historical + projected P&L
B36: Balance Sheet | C36: Historical + projected BS
B37: Cash Flow | C37: Historical + projected CF
B38: Ratios | C38: Financial ratio analysis
B39: DCF | C39: Discounted Cash Flow valuation
B40: Scenarios | C40: Bull / Base / Bear comparison
B41: Investment Memo | C41: Executive summary & recommendation
B43: FORMATTING LEGEND
B44: Blue text | C44: Hardcoded input — editable assumption
B45: Black text | C45: Formula / calculation
B46: Green text | C46: Link to another worksheet
B47: Yellow background | C47: Key assumption needing review

Sheet Assumptions
B1: PayPal (PYPL) — Model Assumptions
B2: All monetary values in USD Millions ($M) | M2: Notes / Source
C3: 2019 | D3: 2020 | E3: 2021 | F3: 2022 | G3: 2023 | H3: 2024 | I3: 2025 | J3: 2026E | K3: 2027E | L3: 2028E
C4: Actual | D4: Actual | E4: Actual | F4: Actual | G4: Actual | H4: Actual | I4: Actual | J4: Forecast | K4: Forecast | L4: Forecast
B6: REVENUE DRIVERS
B7: Total Revenue ($M) | C7: 17772 | D7: 21454 | E7: 25371 | F7: 27518 | G7: 29771 | H7: 31797 | I7: 33172 | J7: 34170 | K7: 35540 | L7: 37320 | M7: Post-Q4'25: ~3% '26, ~4% '27, ~5% '28 recovery
B8: Revenue Growth (%) | D8: 0.20717983 | E8: 0.18257668 | F8: 0.084624177 | G8: 0.081873683 | H8: 0.068052803 | I8: 0.043243073 | J8: 0.03 | K8: 0.04 | L8: 0.05 | M8: Weak '26 guidance; gradual recovery assumed
B9: Gross Margin (%) | C9: 0.43709205 | D9: 0.42887107 | E9: 0.43900516 | F9: 0.44305545 | G9: 0.4492963 | H9: 0.46092399 | I9: 0.46153382 | J9: 0.445 | K9: 0.448 | L9: 0.45 | M9: Flat near-term; modest expansion from mix shift
B11: OPERATING EXPENSE DRIVERS (as % of Revenue)
B12: Total OpEx (% of Revenue) | C12: 0.28702453 | D12: 0.27556633 | E12: 0.273383 | F12: 0.29275383 | G12: 0.28040711 | H12: 0.2810957 | I12: 0.28041722 | J12: 0.29 | K12: 0.285 | L12: 0.28 | M12: CEO transition costs; limited leverage near-term
B13: Operating Margin (%) | C13: 0.15006752 | D13: 0.15330475 | E13: 0.16562217 | F13: 0.15030162 | G13: 0.16888919 | H13: 0.17982829 | I13: 0.1811166 | J13: 0.18 | K13: 0.187 | L13: 0.195 | M13: Gross Margin - Total OpEx %; slow recovery
B14: D&A (% of Revenue) | C14: 0.045577313 | D14: 0.047124079 | E14: 0.047298096 | F14: 0.046296969 | G14: 0.043330758 | H14: 0.03959493 | I14: 0.03858676 | J14: 0.038 | K14: 0.037 | L14: 0.036 | M14: Stable; slight decline
B15: SBC (% of Revenue) | C15: 0.057449921 | D15: 0.064230447 | E15: 0.059516771 | F15: 0.052910822 | G15: 0.046689732 | H15: 0.043997861 | I15: 0.040696973 | J15: 0.04 | K15: 0.039 | L15: 0.038 | M15: Elevated during CEO transition
B17: TAX & INTEREST
B18: Effective Tax Rate (%) | C18: -0.010686395 | D18: -0.38909091 | E18: -0.050125945 | F18: 0.3679122 | G18: 0.089427407 | H18: 0.1413819 | I18: 0.23172906 | J18: 0.2 | K18: 0.2 | L18: 0.2 | M18: Assumed stable effective rate
B19: Interest Expense ($M) | C19: 234 | D19: 264 | E19: 232 | F19: 309 | G19: 365 | H19: 392 | I19: 398 | J19: 410 | K19: 420 | L19: 420 | M19: Slightly higher; debt remains elevated
B21: BALANCE SHEET DRIVERS
B22: Capital Expenditures ($M) | C22: 704 | D22: 866 | E22: 908 | F22: 706 | G22: 596 | H22: 516 | I22: 505 | J22: 900 | K22: 850 | L22: 800 | M22: Mgmt guided ~$1B '26; investment cycle
B23: CapEx (% of Revenue) | C23: 0.039612874 | D23: 0.040365433 | E23: 0.035788893 | F23: 0.025655934 | G23: 0.020019482 | H23: 0.016227946 | I23: 0.015223683 | J23: 0.026 | K23: 0.024 | L23: 0.021 | M23: Higher investment cycle; normalizes by '28
B24: Depreciation & Amortization ($M) | C24: 810 | D24: 1011 | E24: 1200 | F24: 1274 | G24: 1290 | H24: 1259 | I24: 1280 | J24: 1300 | K24: 1320 | L24: 1340 | M24: Source: CF statement; stable
B25: Net PP&E ($M) | C25: 1693 | D25: 1807 | E25: 1909 | F25: 2201 | G25: 1882 | H25: 1581 | I25: 1909 | M25: =Prior PP&E + CapEx - Depreciation (formula in BS) -> #NAME?
B27: WORKING CAPITAL DRIVERS
B28: Current Ratio | C28: 1.4300308 | D28: 1.3263714 | E28: 0.41899649 | F28: 1.2758621 | G28: 1.2909875 | H28: 1.279534 | I28: 1.2867171 | M28: =Current Assets / Current Liabilities (calc in BS) -> #NAME?
B30: DEBT & CAPITAL STRUCTURE
B31: Long-Term Debt ($M) | C31: 4965 | D31: 8939 | E31: 8049 | F31: 10417 | G31: 9676 | H31: 9879 | I31: 9987 | J31: 9900 | K31: 9800 | L31: 9700 | M31: Minimal deleveraging; focus on buybacks
B32: Debt / Equity | C32: 0.29404797 | D32: 0.4465258 | E32: 0.37046072 | F32: 0.51381079 | G32: 0.45964562 | H32: 0.48386149 | I32: 0.4930391 | M32: Total debt / stockholders equity
B33: Net Debt ($M) | C33: -2384 | D33: 4145 | E33: 2852 | F33: 2641 | G33: 595 | H33: 3217 | I33: 1938 | M33: Total Debt - Cash
B34: Share Repurchases ($M) | C34: 3333 | D34: 1021 | E34: 3397 | F34: 4200 | G34: 5100 | H34: 5400 | I34: 6000 | J34: 6000 | K34: 6000 | L34: 6000 | M34: Mgmt guided ~$6B/yr; maintained
B36: DCF VALUATION INPUTS
B37: Risk-Free Rate (%) | C37: 0.042 | M37: 10Y US Treasury yield
B38: Equity Risk Premium (%) | C38: 0.055 | M38: Damodaran 2025 estimate
B39: Beta (levered) | C39: 1.4 | M39: Elevated: CEO change, competitive pressure
B40: Cost of Equity (CAPM) (%) | C40: ← formula | M40: =Rf + Beta * ERP (formula) -> #NAME?
B41: Pre-Tax Cost of Debt (%) | C41: 0.042 | M41: =Interest Expense / Avg Debt -> #NAME?
B42: Tax Rate for WACC (%) | C42: 0.175 | M42: Same as effective tax rate
B43: Target Debt Weight (%) | C43: 0.3 | M43: Based on current capital structure
B44: Target Equity Weight (%) | C44: 0.7 | M44: =1 - Debt Weight -> #NAME?
B45: WACC (%) | C45: ← formula
B47: Terminal Growth Rate (%) | C47: 0.015 | M47: Conservative: below GDP, competitive risk
B48: Exit EV/EBITDA Multiple | C48: ← formula | M48: Alternative terminal value method
...

Sheet Income Statement
B1: PayPal (PYPL) — Consolidated Income Statement
B2: USD Millions ($M) except per-share data | M2: Notes
C3: 2019 | D3: 2020 | E3: 2021 | F3: 2022 | G3: 2023 | H3: 2024 | I3: 2025 | J3: 2026E | K3: 2027E | L3: 2028E
C4: Actual | D4: Actual | E4: Actual | F4: Actual | G4: Actual | H4: Actual | I4: Actual | J4: Forecast | K4: Forecast | L4: Forecast
B6: REVENUE
B7: Total Revenue | C7: 17772 | D7: 21454 | E7: 25371 | F7: 27518 | G7: 29771 | H7: 31797 | I7: 33172 | J7: =Assumptions!J7 -> 34170 | K7: =Assumptions!K7 -> 35540 | L7: =Assumptions!L7 -> 37320 | M7: Source: Assumptions tab
B8: YoY Growth (%) | D8: 0.20717983 | E8: 0.18257668 | F8: 0.084624177 | G8: 0.081873683 | H8: 0.068052803 | I8: 0.043243073 | J8: =(J7-I7)/I7 -> 0.030085614 | K8: =(K7-J7)/J7 -> 0.040093649 | L8: =(L7-K7)/K7 -> 0.050084412
B11: COST OF REVENUE
B12: Cost of Revenue | C12: 10004 | D12: 12253 | E12: 14233 | F12: 15326 | G12: 16395 | H12: 17141 | I12: 17862 | J12: =J7*(1-Assumptions!J9) -> 18964.35 | K12: =K7*(1-Assumptions!K9) -> 19618.08 | L12: =L7*(1-Assumptions!L9) -> 20526 | M12: Revenue × (1 - Gross Margin %)
B13: % of Revenue | C13: 0.56290795 | D13: 0.57112893 | E13: 0.56099484 | F13: 0.55694455 | G13: 0.5507037 | H13: 0.53907601 | I13: 0.53846618 | J13: =J12/J7 -> 0.555 | K13: =K12/K7 -> 0.552 | L13: =L12/L7 -> 0.55
B15: Gross Profit | C15: 7768 | D15: 9201 | E15: 11138 | F15: 12192 | G15: 13376 | H15: 14656 | I15: 15310 | J15: =J7-J12 -> 15205.65 | K15: =K7-K12 -> 15921.92 | L15: =L7-L12 -> 16794 | M15: Revenue - COGS
B16: Gross Margin (%) | C16: 0.43709205 | D16: 0.42887107 | E16: 0.43900516 | F16: 0.44305545 | G16: 0.4492963 | H16: 0.46092399 | I16: 0.46153382 | J16: =J15/J7 -> 0.445 | K16: =K15/K7 -> 0.448 | L16: =L15/L7 -> 0.45 | M16: Should match Assumptions tab gross margin
B19: OPERATING EXPENSES
B20: Total Operating Expenses | C20: 5101 | D20: 5912 | E20: 6936 | F20: 8056 | G20: 8348 | H20: 8938 | I20: 9302 | J20: =J7*Assumptions!J12 -> 9909.3 | K20: =K7*Assumptions!K12 -> 10128.9 | L20: =L7*Assumptions!L12 -> 10449.6 | M20: Revenue × Total OpEx % (from Assumptions)
B21: % of Revenue | C21: 0.28702453 | D21: 0.27556633 | E21: 0.273383 | F21: 0.29275383 | G21: 0.28040711 | H21: 0.2810957 | I21: 0.28041722 | J21: =J20/J7 -> 0.29 | K21: =K20/K7 -> 0.285 | L21: =L20/L7 -> 0.28
B23: Operating Income (EBIT) | C23: 2667 | D23: 3289 | E23: 4202 | F23: 4136 | G23: 5028 | H23: 5718 | I23: 6008 | J23: =J15-J20 -> 5296.35 | K23: =K15-K20 -> 5793.02 | L23: =L15-L20 -> 6344.4 | M23: Gross Profit - Operating Expenses
B24: Operating Margin (%) | C24: 0.15006752 | D24: 0.15330475 | E24: 0.16562217 | F24: 0.15030162 | G24: 0.16888919 | H24: 0.17982829 | I24: 0.1811166 | J24: =J23/J7 -> 0.155 | K24: =K23/K7 -> 0.163 | L24: =L23/L7 -> 0.17
B27: NON-OPERATING ITEMS
B28: Interest Income | C28: 93 | D28: 48 | E28: 23 | F28: 150 | G28: 482 | H28: 532 | I28: 498 | J28: =380 -> 380 | K28: =350 -> 350 | L28: =330 -> 330 | M28: Lower rates headwind per Q4'25 guidance
B29: Interest Expense | C29: -234 | D29: -264 | E29: -232 | F29: -309 | G29: -365 | H29: -392 | I29: -398 | J29: =-Assumptions!J19 -> -410 | K29: =-Assumptions!K19 -> -420 | L29: =-Assumptions!L19 -> -420 | M29: From Assumptions tab (shown as negative)
B30: Other Income (Expense) | C30: 120 | D30: 1776 | E30: -16 | F30: -494 | G30: -64 | H30: 10 | I30: -271 | J30: =0 -> 0 | K30: =0 -> 0 | L30: =0 -> 0 | M30: Volatile & unpredictable; conservatively set to $0
B32: Income Before Taxes | C32: 2646 | D32: 4849 | E32: 3977 | F32: 3483 | G32: 5081 | H32: 5868 | I32: 5837 | J32: =J23+J28+J29+J30 -> 5266.35 | K32: =K23+K28+K29+K30 -> 5723.02 | L32: =L23+L28+L29+L30 -> 6254.4 | M32: EBIT + Interest Inc + Interest Exp + Other
B35: TAXES
B36: Income Tax Expense | C36: 187 | D36: 647 | E36: -192 | F36: 1064 | G36: 835 | H36: 1295 | I36: 1527 | J36: =J32*Assumptions!J18 -> 1053.27 | K36: =K32*Assumptions!K18 -> 1144.604 | L36: =L32*Assumptions!L18 -> 1250.88 | M36: EBT × Effective Tax Rate (from Assumptions)
B37: Effective Tax Rate (%) | C37: 0.070672714 | D37: 0.13342957 | E37: -0.048277596 | F37: 0.30548378 | G37: 0.16433773 | H37: 0.22068848 | I37: 0.26160699 | J37: =IF(J32=0,0,J36/J32) -> 0.2 | K37: =IF(K32=0,0,K36/K32) -> 0.2 | L37: =IF(L32=0,0,L36/L32) -> 0.2
B39: Net Income | C39: 2459 | D39: 4202 | E39: 4169 | F39: 2419 | G39: 4246 | H39: 4573 | I39: 4310 | J39: =J32-J36 -> 4213.08 | K39: =K32-K36 -> 4578.416 | L39: =L32-L36 -> 5003.52 | M39: EBT - Tax Expense
B40: Net Margin (%) | C40: 0.13836372 | D40: 0.19586091 | E40: 0.16432147 | F40: 0.087906098 | G40: 0.14262201 | H40: 0.1438186 | I40: 0.12992886 | J40: =J39/J7 -> 0.12329763 | K40: =K39/K7 -> 0.12882431 | L40: =L39/L7 -> 0.13407074
B41: YoY Growth (%) | D41: 0.70882473 | E41: -0.0078534031 | F41: -0.41976493 | G41: 0.75527077 | H41: 0.07701366 | I41: -0.05751148 | J41: =(J39-I39)/ABS(I39) -> -0.022487239 | K41: =(K39-J39)/ABS(J39) -> 0.086714708 | L41: =(L39-K39)/ABS(K39) -> 0.092849579
B44: PER SHARE DATA
B45: Diluted Shares Outstanding (M) | C45: 1188 | D45: 1187 | E45: 1183 | F45: 1156 | G45: 1105 | H45: 1053 | I45: 941 | J45: 940 | K45: 890 | L45: 840 | M45: Accelerated buyback at lower share price
B46: Diluted EPS | C46: 2.07 | D46: 3.54 | E46: 3.52 | F46: 2.09 | G46: 3.84 | H46: 4.34 | I46: 4.58 | J46: =J39/J45 -> 4.482 | K46: =K39/K45 -> 5.1442876 | L46: =L39/L45 -> 5.9565714 | M46: Net Income / Diluted Shares
B47: EPS Growth (%) | D47: 0.71014493 | E47: -0.0056497175 | F47: -0.40625 | G47: 0.83732057 | H47: 0.13020833 | I47: 0.055299539 | J47: =(J46-I46)/ABS(I46) -> -0.02139738 | K47: =(K46-J46)/ABS(J46) -> 0.1477661 | L47: =(L46-K46)/ABS(K46) -> 0.15790015
B50: Row Reference Map (for model linking):
B51: Revenue: Row 7
B52: COGS: Row 12
B53: Gross Profit: Row 15
B54: OpEx: Row 20
B55: Operating Income: Row 23
B56: EBT: Row 32
B57: Tax: Row 36
...

Sheet Balance Sheet
B1: PayPal (PYPL) — Consolidated Balance Sheet
B2: USD Millions ($M) — As of December 31 | M2: Notes
C3: 2019 | D3: 2020 | E3: 2021 | F3: 2022 | G3: 2023 | H3: 2024 | I3: 2025 | J3: 2026E | K3: 2027E | L3: 2028E
C4: Actual | D4: Actual | E4: Actual | F4: Actual | G4: Actual | H4: Actual | I4: Actual | J4: Forecast | K4: Forecast | L4: Forecast
B6: CURRENT ASSETS
B7: Cash & Cash Equivalents | C7: 7349 | D7: 4794 | E7: 5197 | F7: 7776 | G7: 9081 | H7: 6662 | I7: 8049 | J7: ='Cash Flow'!J44 -> 7858.3586 | K7: ='Cash Flow'!K44 -> 8504.1075 | L7: ='Cash Flow'!L44 -> 10114.873 | M7: LINKED to Cash Flow Ending Balance (model is closed)
B8: Short-Term Investments | C8: 3412 | D8: 8289 | E8: 109 | F8: 3075 | G8: 4976 | H8: 4261 | I8: 2373 | J8: =I8 -> 2373 | K8: =J8 -> 2373 | L8: =K8 -> 2373 | M8: Held constant (no material change assumed)
B9: Accounts Receivable | C9: 435 | D9: 577 | E9: 12723 | F9: 2201 | G9: 1882 | H9: 1581 | I9: 1909 | J9: =I9*('Income Statement'!J7/'Income Statement'!I7) -> 1966.4334 | K9: =J9*('Income Statement'!K7/'Income Statement'!J7) -> 2045.2749 | L9: =K9*('Income Statement'!L7/'Income Statement'!K7) -> 2147.7113 | M9: Grows proportionally with revenue
B10: Customer Accounts & Other Current | C10: 27299 | D10: 37335 | E10: 0 | F10: 44372 | G10: 46630 | H10: 45702 | I10: 47428 | J10: =I10*1.03 -> 48850.84 | K10: =J10*1.03 -> 50316.365 | L10: =K10*1.03 -> 51825.856 | M10: Grows ~3% (tied to payment volume growth)
B12: Total Current Assets | C12: 38495 | D12: 50995 | E12: 18029 | F12: 57424 | G12: 62569 | H12: 58206 | I12: 59759 | J12: =SUM(J7:J10) -> 61048.632 | K12: =SUM(K7:K10) -> 63238.748 | L12: =SUM(L7:L10) -> 66461.44 | M12: Sum of current asset items
B15: NON-CURRENT ASSETS
B16: Property & Equipment, Net | C16: 1693 | D16: 1807 | E16: 1909 | F16: 2201 | G16: 1882 | H16: 1581 | I16: 1909 | J16: =I16+Assumptions!J22-Assumptions!J24 -> 1509 | K16: =J16+Assumptions!K22-Assumptions!K24 -> 1039 | L16: =K16+Assumptions!L22-Assumptions!L24 -> 499 | M16: Prior PP&E + CapEx - D&A
B17: Goodwill | C17: 6212 | D17: 9135 | E17: 11454 | F17: 11209 | G17: 11026 | H17: 10837 | I17: 10864 | J17: =I17 -> 10864 | K17: =J17 -> 10864 | L17: =K17 -> 10864 | M17: Held constant (no acquisitions assumed)
B18: Intangible Assets | C18: 778 | D18: 1048 | E18: 1332 | F18: 1730 | G18: 1488 | H18: 1508 | I18: 1700 | J18: =I18 -> 1700 | K18: =J18 -> 1700 | L18: =K18 -> 1700 | M18: Held constant (no acquisitions assumed)
B19: Other Non-Current Assets | C19: 4155 | D19: 7394 | E19: 43079 | F19: 6060 | G19: 5201 | H19: 6593 | I19: 5941 | J19: =I19 -> 5941 | K19: =J19 -> 5941 | L19: =K19 -> 5941 | M19: Held stable; immaterial changes assumed
B21: Total Assets | C21: 51333 | D21: 70379 | E21: 75803 | F21: 78624 | G21: 82166 | H21: 78725 | I21: 80173 | J21: =J12+J16+J17+J18+J19 -> 81062.632 | K21: =K12+K16+K17+K18+K19 -> 82782.748 | L21: =L12+L16+L17+L18+L19 -> 85465.44 | M21: Current Assets + Non-Current Assets
B25: CURRENT LIABILITIES
B26: Accounts Payable | C26: 232 | D26: 252 | E26: 197 | F26: 40140 | G26: 42074 | H26: 39898 | I26: 40438 | J26: =I26*('Income Statement'!J7/'Income Statement'!I7) -> 41654.602 | K26: =J26*('Income Statement'!K7/'Income Statement'!J7) -> 43324.687 | L26: =K26*('Income Statement'!L7/'Income Statement'!K7) -> 45494.579 | M26: Grows proportionally with revenue
B27: Accrued Expenses & Other Current | C27: 26687 | D27: 38195 | E27: 42832 | F27: 4868 | G27: 6392 | H27: 5592 | I27: 6005 | J27: =I27*1.03 -> 6185.15 | K27: =J27*1.03 -> 6370.7045 | L27: =K27*1.03 -> 6561.8256 | M27: Grows ~3% annually; estimate
B29: Total Current Liabilities | C29: 26919 | D29: 38447 | E29: 43029 | F29: 45008 | G29: 48466 | H29: 45490 | I29: 46443 | J29: =J26+J27 -> 47839.752 | K29: =K26+K27 -> 49695.392 | L29: =L26+L27 -> 52056.404 | M29: Sum of current liability items
B32: NON-CURRENT LIABILITIES
B33: Long-Term Debt | C33: 4965 | D33: 8939 | E33: 8049 | F33: 10417 | G33: 9676 | H33: 9879 | I33: 9987 | J33: =Assumptions!J31 -> 9900 | K33: =Assumptions!K31 -> 9800 | L33: =Assumptions!L31 -> 9700 | M33: From Assumptions tab (gradual deleveraging)
B34: Other Non-Current Liabilities | C34: 2520 | D34: 2930 | E34: 2998 | F34: 2925 | G34: 2973 | H34: 2939 | I34: 3487 | J34: =I34 -> 3487 | K34: =J34 -> 3487 | L34: =K34 -> 3487 | M34: Held stable
B36: Total Liabilities | C36: 34404 | D36: 50316 | E36: 54076 | F36: 58350 | G36: 61115 | H36: 58308 | I36: 59917 | J36: =J29+J33+J34 -> 61226.752 | K36: =K29+K33+K34 -> 62982.392 | L36: =L29+L33+L34 -> 65243.404 | M36: Current Liab + Non-Current Liab
B40: STOCKHOLDERS' EQUITY
B41: Common Stock & APIC | C41: 15588 | D41: 16644 | E41: 0 | F41: 18327 | G41: 19642 | H41: 20705 | I41: 21582 | J41: =I41+Assumptions!J7*Assumptions!J15 -> 22948.8 | K41: =J41+Assumptions!K7*Assumptions!K15 -> 24334.86 | L41: =K41+Assumptions!L7*Assumptions!L15 -> 25753.02 | M41: Prior + SBC (from Assumptions SBC pct x Revenue)
B42: Retained Earnings | C42: 8342 | D42: 12366 | E42: 16535 | F42: 18954 | G42: 23200 | H42: 27347 | I42: 32470 | J42: =I42+'Income Statement'!J39 -> 36683.08 | K42: =J42+'Income Statement'!K39 -> 41261.496 | L42: =K42+'Income Statement'!L39 -> 46265.016 | M42: Prior RE + Net Income (buybacks via Treasury Stock)
B43: Treasury Stock | C43: -6872 | D43: -8507 | E43: 0 | F43: -16079 | G43: -21045 | H43: -27085 | I43: -33138 | J43: =I43-Assumptions!J34 -> -39138 | K43: =J43-Assumptions!K34 -> -45138 | L43: =K43-Assumptions!L34 -> -51138 | M43: Prior Treasury - Buybacks (more negative)
B44: AOCI & Other Adjustments | C44: -173 | D44: -484 | E44: -808 | F44: -928 | G44: -746 | H44: -550 | I44: -658 | J44: =I44 -> -658 | K44: =J44 -> -658 | L44: =K44 -> -658 | M44: Held constant (unpredictable, immaterial)
B46: Total Stockholders' Equity | C46: 16885 | D46: 20019 | E46: 21727 | F46: 20274 | G46: 21051 | H46: 20417 | I46: 20256 | J46: =J41+J42+J43+J44 -> 19835.88 | K46: =K41+K42+K43+K44 -> 19800.356 | L46: =L41+L42+L43+L44 -> 20222.036 | M46: APIC + RE + Treasury + AOCI
B48: Total Liabilities & Equity | C48: 51333 | D48: 70379 | E48: 75803 | F48: 78624 | G48: 82166 | H48: 78725 | I48: 80173 | J48: =J36+J46 -> 81062.632 | K48: =K36+K46 -> 82782.748 | L48: =L36+L46 -> 85465.44 | M48: Total Liabilities + Total Equity
B51: BALANCE CHECK
B52: Difference (Assets - L&E) | C52: 0 | D52: 0 | E52: 0 | F52: 0 | G52: 0 | H52: 0 | I52: 0 | J52: =J21-J48 -> 0 | K52: =K21-K48 -> 0 | L52: =L21-L48 -> 0 | M52: MUST BE $0 — model integrity check
B54: ✓ If all zeros → model is balanced
B55: ✗ If non-zero → check formulas for errors
B58: Row Reference Map (for Cash Flow linking):
B59: Cash: Row 7
B60: ST Investments: Row 8
B61: AR: Row 9
B62: Customer Accts: Row 10
...

Sheet Cash Flow
B1: PayPal (PYPL) — Consolidated Cash Flow Statement
B2: USD Millions ($M) | M2: Notes
C3: 2019 | D3: 2020 | E3: 2021 | F3: 2022 | G3: 2023 | H3: 2024 | I3: 2025 | J3: 2026E | K3: 2027E | L3: 2028E
C4: Actual | D4: Actual | E4: Actual | F4: Actual | G4: Actual | H4: Actual | I4: Actual | J4: Forecast | K4: Forecast | L4: Forecast
B6: CASH FROM OPERATING ACTIVITIES
B7: Net Income | C7: 2459 | D7: 4202 | E7: 4169 | F7: 2419 | G7: 4246 | H7: 4573 | I7: 4310 | J7: ='Income Statement'!J39 -> 4213.08 | K7: ='Income Statement'!K39 -> 4578.416 | L7: ='Income Statement'!L39 -> 5003.52 | M7: From Income Statement (green = cross-sheet link)
B9: Adjustments for non-cash items:
B10: (+) Depreciation & Amortization | C10: 810 | D10: 1011 | E10: 1200 | F10: 1274 | G10: 1290 | H10: 1259 | I10: 1280 | J10: =Assumptions!J24 -> 1300 | K10: =Assumptions!K24 -> 1320 | L10: =Assumptions!L24 -> 1340 | M10: From Assumptions tab (non-cash add-back)
B11: (+) Stock-Based Compensation | C11: 1021 | D11: 1378 | E11: 1510 | F11: 1456 | G11: 1390 | H11: 1399 | I11: 1350 | J11: =Assumptions!J7*Assumptions!J15 -> 1366.8 | K11: =Assumptions!K7*Assumptions!K15 -> 1386.06 | L11: =Assumptions!L7*Assumptions!L15 -> 1418.16 | M11: Revenue x SBC % (non-cash add-back)
B13: Changes in working capital:
B14: (Inc)/Dec in Accounts Receivable | D14: -142 | E14: -12146 | F14: 10522 | G14: 319 | H14: 301 | I14: -328 | J14: =-('Balance Sheet'!J9-'Balance Sheet'!I9) -> -57.433438 | K14: =-('Balance Sheet'!K9-'Balance Sheet'!J9) -> -78.841493 | L14: =-('Balance Sheet'!L9-'Balance Sheet'!K9) -> -102.43639 | M14: Negative when AR increases (cash tied up)
B15: (Inc)/Dec in Customer Accounts | D15: -10036 | E15: 37335 | F15: -44372 | G15: -2258 | H15: 928 | I15: -1726 | J15: =-('Balance Sheet'!J10-'Balance Sheet'!I10) -> -1422.84 | K15: =-('Balance Sheet'!K10-'Balance Sheet'!J10) -> -1465.5252 | L15: =-('Balance Sheet'!L10-'Balance Sheet'!K10) -> -1509.491 | M15: Large PayPal-specific item (customer funds)
B16: Inc/(Dec) in Accounts Payable | D16: 20 | E16: -55 | F16: 39943 | G16: 1934 | H16: -2176 | I16: 540 | J16: ='Balance Sheet'!J26-'Balance Sheet'!I26 -> 1216.6021 | K16: ='Balance Sheet'!K26-'Balance Sheet'!J26 -> 1670.085 | L16: ='Balance Sheet'!L26-'Balance Sheet'!K26 -> 2169.8915 | M16: Positive when AP increases (cash preserved)
B17: Inc/(Dec) in Accrued Expenses | D17: 11508 | E17: 4637 | F17: -37964 | G17: 1524 | H17: -800 | I17: 413 | J17: ='Balance Sheet'!J27-'Balance Sheet'!I27 -> 180.15 | K17: ='Balance Sheet'!K27-'Balance Sheet'!J27 -> 185.5545 | L17: ='Balance Sheet'!L27-'Balance Sheet'!K27 -> 191.12114 | M17: Positive when accrued liabilities increase
B18: Other Operating Adjustments | C18: 272 | D18: -738 | E18: -536 | F18: 664 | G18: -2083 | H18: -831 | I18: 180 | J18: =0 -> 0 | K18: =0 -> 0 | L18: =0 -> 0 | M18: Conservatively zero for forecast
B20: Cash from Operations | C20: 4562 | D20: 5853 | E20: 6343 | F20: 5813 | G20: 4843 | H20: 6400 | I20: 7120 | J20: =J7+J10+J11+J14+J15+J16+J17+J18 -> 6796.3586 | K20: =K7+K10+K11+K14+K15+K16+K17+K18 -> 7595.7488 | L20: =L7+L10+L11+L14+L15+L16+L17+L18 -> 8510.7653 | M20: NI + Non-cash + Working Capital Changes
B21: CFO Margin (% of Revenue) | C21: 0.25669593 | D21: 0.27281626 | E21: 0.25000985 | F21: 0.21124355 | G21: 0.16267509 | H21: 0.20127685 | I21: 0.21463885 | J21: =J20/'Income Statement'!J7 -> 0.19889841 | K21: =K20/'Income Statement'!K7 -> 0.21372394 | L21: =L20/'Income Statement'!L7 -> 0.22804837
B24: CASH FROM INVESTING ACTIVITIES
B25: Capital Expenditures | C25: -704 | D25: -866 | E25: -908 | F25: -706 | G25: -596 | H25: -516 | I25: -505 | J25: =-Assumptions!J22 -> -900 | K25: =-Assumptions!K22 -> -850 | L25: =-Assumptions!L22 -> -800 | M25: From Assumptions (shown as negative)
B26: Other Investing Activities | C26: -1871 | D26: -7030 | E26: -3087 | F26: -1050 | G26: -1200 | H26: 800 | I26: -500 | J26: =0 -> 0 | K26: =0 -> 0 | L26: =0 -> 0 | M26: Conservatively zero (no acquisitions assumed)
B28: Cash from Investing | C28: -2575 | D28: -7896 | E28: -3995 | F28: -1756 | G28: -1796 | H28: 284 | I28: -1005 | J28: =J25+J26 -> -900 | K28: =K25+K26 -> -850 | L28: =L25+L26 -> -800 | M28: CapEx + Other Investing
B31: CASH FROM FINANCING ACTIVITIES
B32: Debt Issuance / (Repayment) | C32: 1996 | D32: 3994 | E32: -990 | F32: 2398 | G32: -741 | H32: 203 | I32: 108 | J32: ='Balance Sheet'!J33-'Balance Sheet'!I33 -> -87 | K32: ='Balance Sheet'!K33-'Balance Sheet'!J33 -> -100 | L32: ='Balance Sheet'!L33-'Balance Sheet'!K33 -> -100 | M32: Change in LT Debt from Balance Sheet
B33: Share Repurchases | C33: -3333 | D33: -1021 | E33: -3397 | F33: -4200 | G33: -5100 | H33: -5400 | I33: -6000 | J33: =-Assumptions!J34 -> -6000 | K33: =-Assumptions!K34 -> -6000 | L33: =-Assumptions!L34 -> -6000 | M33: From Assumptions (shown as negative cash outflow)
B34: Other Financing Activities | C34: -308 | D34: -350 | E34: -240 | F34: -100 | G34: -230 | H34: -150 | I34: -200 | J34: =0 -> 0 | K34: =0 -> 0 | L34: =0 -> 0 | M34: Set to zero (no BS counterpart; immaterial)
B36: Cash from Financing | C36: -1645 | D36: 2623 | E36: -4627 | F36: -1902 | G36: -6071 | H36: -5347 | I36: -6092 | J36: =J32+J33+J34 -> -6087 | K36: =K32+K33+K34 -> -6100 | L36: =L32+L33+L34 -> -6100 | M36: Debt changes + Buybacks + Other
B40: CASH SUMMARY
B41: Net Change in Cash | C41: 342 | D41: 580 | E41: -2279 | F41: 4155 | G41: -3024 | H41: 1337 | I41: 23 | J41: =J20+J28+J36 -> -190.64136 | K41: =K20+K28+K36 -> 645.74882 | L41: =L20+L28+L36 -> 1610.7653 | M41: CFO + CFI + CFF
B43: Beginning Cash Balance | C43: 7007 | D43: 7349 | E43: 4794 | F43: 5197 | G43: 7776 | H43: 9081 | I43: 6662 | J43: ='Balance Sheet'!I7 -> 8049 | K43: =J44 -> 7858.3586 | L43: =K44 -> 8504.1075 | M43: Prior year ending cash balance
B44: Ending Cash Balance | C44: 7349 | D44: 4794 | E44: 5197 | F44: 7776 | G44: 9081 | H44: 6662 | I44: 8049 | J44: =J43+J41 -> 7858.3586 | K44: =K43+K41 -> 8504.1075 | L44: =L43+L41 -> 10114.873 | M44: THIS LINKS BACK TO BALANCE SHEET CASH ROW
B48: FREE CASH FLOW (for DCF)
B49: Free Cash Flow (CFO - CapEx) | C49: 3858 | D49: 4987 | E49: 5435 | F49: 5107 | G49: 4247 | H49: 5884 | I49: 6615 | J49: =J20+J25 -> 5896.3586 | K49: =K20+K25 -> 6745.7488 | L49: =L20+L25 -> 7710.7653 | M49: Key input for DCF valuation
B50: FCF Margin (% of Revenue) | C50: 0.21708305 | D50: 0.23245083 | E50: 0.21422096 | F50: 0.18558762 | G50: 0.1426556 | H50: 0.1850489 | I50: 0.19941517 | J50: =J49/'Income Statement'!J7 -> 0.17255952 | K50: =K49/'Income Statement'!K7 -> 0.18980723 | L50: =L49/'Income Statement'!L7 -> 0.20661215
B51: FCF per Share | C51: 3.25 | D51: 4.2 | E51: 4.59 | F51: 4.42 | G51: 3.84 | H51: 5.59 | I51: 7.03 | J51: =J49/'Income Statement'!J45 -> 6.272722 | K51: =K49/'Income Statement'!K45 -> 7.5794931 | L51: =L49/'Income Statement'!L45 -> 9.1794825 | M51: FCF / Diluted Shares (from IS)
B54: Row Reference Map (for DCF linking):
B55: Net Income: Row 7
B56: D&A: Row 10
B57: SBC: Row 11
B58: CFO: Row 20
B59: CapEx: Row 25
...

Sheet Ratios
B1: PayPal (PYPL) — Financial Ratio Analysis
B2: All ratios calculated from linked financial statements | M2: Formula
C3: 2019 | D3: 2020 | E3: 2021 | F3: 2022 | G3: 2023 | H3: 2024 | I3: 2025 | J3: 2026E | K3: 2027E | L3: 2028E
C4: Actual | D4: Actual | E4: Actual | F4: Actual | G4: Actual | H4: Actual | I4: Actual | J4: Forecast | K4: Forecast | L4: Forecast
B6: PROFITABILITY
B7: Gross Margin | C7: ='Income Statement'!C15/'Income Statement'!C7 -> 0.43709205 | D7: ='Income Statement'!D15/'Income Statement'!D7 -> 0.42887107 | E7: ='Income Statement'!E15/'Income Statement'!E7 -> 0.43900516 | F7: ='Income Statement'!F15/'Income Statement'!F7 -> 0.44305545 | G7: ='Income Statement'!G15/'Income Statement'!G7 -> 0.4492963 | H7: ='Income Statement'!H15/'Income Statement'!H7 -> 0.46092399 | I7: ='Income Statement'!I15/'Income Statement'!I7 -> 0.46153382 | J7: ='Income Statement'!J15/'Income Statement'!J7 -> 0.445 | ... L7: ='Income Statement'!L15/'Income Statement'!L7 -> 0.45 | M7: Gross Profit / Revenue
B8: Operating Margin | C8: ='Income Statement'!C23/'Income Statement'!C7 -> 0.15006752 | D8: ='Income Statement'!D23/'Income Statement'!D7 -> 0.15330475 | E8: ='Income Statement'!E23/'Income Statement'!E7 -> 0.16562217 | F8: ='Income Statement'!F23/'Income Statement'!F7 -> 0.15030162 | G8: ='Income Statement'!G23/'Income Statement'!G7 -> 0.16888919 | H8: ='Income Statement'!H23/'Income Statement'!H7 -> 0.17982829 | I8: ='Income Statement'!I23/'Income Statement'!I7 -> 0.1811166 | J8: ='Income Statement'!J23/'Income Statement'!J7 -> 0.155 | ... L8: ='Income Statement'!L23/'Income Statement'!L7 -> 0.17 | M8: EBIT / Revenue
B9: Net Margin | C9: ='Income Statement'!C39/'Income Statement'!C7 -> 0.13836372 | D9: ='Income Statement'!D39/'Income Statement'!D7 -> 0.19586091 | E9: ='Income Statement'!E39/'Income Statement'!E7 -> 0.16432147 | F9: ='Income Statement'!F39/'Income Statement'!F7 -> 0.087906098 | G9: ='Income Statement'!G39/'Income Statement'!G7 -> 0.14262201 | H9: ='Income Statement'!H39/'Income Statement'!H7 -> 0.1438186 | I9: ='Income Statement'!I39/'Income Statement'!I7 -> 0.12992886 | J9: ='Income Statement'!J39/'Income Statement'!J7 -> 0.12329763 | ... L9: ='Income Statement'!L39/'Income Statement'!L7 -> 0.13407074 | M9: Net Income / Revenue
B10: EBITDA Margin | C10: =('Income Statement'!C23+Assumptions!C24)/'Income Statement'!C7 -> 0.19564483 | D10: =('Income Statement'!D23+Assumptions!D24)/'Income Statement'!D7 -> 0.20042882 | E10: =('Income Statement'!E23+Assumptions!E24)/'Income Statement'!E7 -> 0.21292026 | F10: =('Income Statement'!F23+Assumptions!F24)/'Income Statement'!F7 -> 0.19659859 | G10: =('Income Statement'!G23+Assumptions!G24)/'Income Statement'!G7 -> 0.21221995 | H10: =('Income Statement'!H23+Assumptions!H24)/'Income Statement'!H7 -> 0.21942322 | I10: =('Income Statement'!I23+Assumptions!I24)/'Income Statement'!I7 -> 0.21970336 | J10: =('Income Statement'!J23+Assumptions!J24)/'Income Statement'!J7 -> 0.19304507 | ... L10: =('Income Statement'!L23+Assumptions!L24)/'Income Statement'!L7 -> 0.20590568 | M10: (EBIT + D&A) / Revenue
B11: FCF Margin | C11: ='Cash Flow'!C49/'Income Statement'!C7 -> 0.21708305 | D11: ='Cash Flow'!D49/'Income Statement'!D7 -> 0.23245083 | E11: ='Cash Flow'!E49/'Income Statement'!E7 -> 0.21422096 | F11: ='Cash Flow'!F49/'Income Statement'!F7 -> 0.18558762 | G11: ='Cash Flow'!G49/'Income Statement'!G7 -> 0.1426556 | H11: ='Cash Flow'!H49/'Income Statement'!H7 -> 0.1850489 | I11: ='Cash Flow'!I49/'Income Statement'!I7 -> 0.19941517 | J11: ='Cash Flow'!J49/'Income Statement'!J7 -> 0.17255952 | ... L11: ='Cash Flow'!L49/'Income Statement'!L7 -> 0.20661215 | M11: Free Cash Flow / Revenue
B14: RETURNS
B15: Return on Equity (ROE) | C15: ='Income Statement'!C39/'Balance Sheet'!C46 -> 0.14563222 | D15: ='Income Statement'!D39/'Balance Sheet'!D46 -> 0.20990059 | E15: ='Income Statement'!E39/'Balance Sheet'!E46 -> 0.19188107 | F15: ='Income Statement'!F39/'Balance Sheet'!F46 -> 0.11931538 | G15: ='Income Statement'!G39/'Balance Sheet'!G46 -> 0.20170063 | H15: ='Income Statement'!H39/'Balance Sheet'!H46 -> 0.22398002 | I15: ='Income Statement'!I39/'Balance Sheet'!I46 -> 0.21277646 | J15: ='Income Statement'!J39/'Balance Sheet'!J46 -> 0.21239693 | ... L15: ='Income Statement'!L39/'Balance Sheet'!L46 -> 0.24742909 | M15: Net Income / Total Equity
B16: Return on Assets (ROA) | C16: ='Income Statement'!C39/'Balance Sheet'!C21 -> 0.047902908 | D16: ='Income Statement'!D39/'Balance Sheet'!D21 -> 0.05970531 | E16: ='Income Statement'!E39/'Balance Sheet'!E21 -> 0.054997823 | F16: ='Income Statement'!F39/'Balance Sheet'!F21 -> 0.030766687 | G16: ='Income Statement'!G39/'Balance Sheet'!G21 -> 0.051675876 | H16: ='Income Statement'!H39/'Balance Sheet'!H21 -> 0.058088282 | I16: ='Income Statement'!I39/'Balance Sheet'!I21 -> 0.053758747 | J16: ='Income Statement'!J39/'Balance Sheet'!J21 -> 0.051973146 | ... L16: ='Income Statement'!L39/'Balance Sheet'!L21 -> 0.058544366 | M16: Net Income / Total Assets
B17: ROIC | C17: ='Income Statement'!C23*(1-Assumptions!C18)/('Balance Sheet'!C21-'Balance Sheet'!C7) -> 0.061283663 | D17: ='Income Statement'!D23*(1-Assumptions!D18)/('Balance Sheet'!D21-'Balance Sheet'!D7) -> 0.069661051 | E17: ='Income Statement'!E23*(1-Assumptions!E18)/('Balance Sheet'!E21-'Balance Sheet'!E7) -> 0.062496519 | F17: ='Income Statement'!F23*(1-Assumptions!F18)/('Balance Sheet'!F21-'Balance Sheet'!F7) -> 0.036900338 | G17: ='Income Statement'!G23*(1-Assumptions!G18)/('Balance Sheet'!G21-'Balance Sheet'!G7) -> 0.062644305 | H17: ='Income Statement'!H23*(1-Assumptions!H18)/('Balance Sheet'!H21-'Balance Sheet'!H7) -> 0.068128975 | I17: ='Income Statement'!I23*(1-Assumptions!I18)/('Balance Sheet'!I21-'Balance Sheet'!I7) -> 0.063997724 | J17: ='Income Statement'!J23*(1-Assumptions!J18)/('Balance Sheet'!J21-'Balance Sheet'!J7) -> 0.057880227 | ... L17: ='Income Statement'!L23*(1-Assumptions!L18)/('Balance Sheet'!L21-'Balance Sheet'!L7) -> 0.06735875 | M17: NOPAT / Invested Capital
B20: LIQUIDITY
B21: Current Ratio | C21: ='Balance Sheet'!C12/'Balance Sheet'!C29 -> 1.4300308 | D21: ='Balance Sheet'!D12/'Balance Sheet'!D29 -> 1.3263714 | E21: ='Balance Sheet'!E12/'Balance Sheet'!E29 -> 0.41899649 | F21: ='Balance Sheet'!F12/'Balance Sheet'!F29 -> 1.2758621 | G21: ='Balance Sheet'!G12/'Balance Sheet'!G29 -> 1.2909875 | H21: ='Balance Sheet'!H12/'Balance Sheet'!H29 -> 1.279534 | I21: ='Balance Sheet'!I12/'Balance Sheet'!I29 -> 1.2867171 | J21: ='Balance Sheet'!J12/'Balance Sheet'!J29 -> 1.2761068 | ... L21: ='Balance Sheet'!L12/'Balance Sheet'!L29 -> 1.2767198 | M21: Current Assets / Current Liabilities
B24: LEVERAGE
B25: Debt / Equity | C25: ='Balance Sheet'!C33/'Balance Sheet'!C46 -> 0.29404797 | D25: ='Balance Sheet'!D33/'Balance Sheet'!D46 -> 0.4465258 | E25: ='Balance Sheet'!E33/'Balance Sheet'!E46 -> 0.37046072 | F25: ='Balance Sheet'!F33/'Balance Sheet'!F46 -> 0.51381079 | G25: ='Balance Sheet'!G33/'Balance Sheet'!G46 -> 0.45964562 | H25: ='Balance Sheet'!H33/'Balance Sheet'!H46 -> 0.48386149 | I25: ='Balance Sheet'!I33/'Balance Sheet'!I46 -> 0.4930391 | J25: ='Balance Sheet'!J33/'Balance Sheet'!J46 -> 0.49909558 | ... L25: ='Balance Sheet'!L33/'Balance Sheet'!L46 -> 0.47967475 | M25: LT Debt / Total Equity
B26: Net Debt / EBITDA | C26: =('Balance Sheet'!C33-'Balance Sheet'!C7)/('Income Statement'!C23+Assumptions!C24) -> -0.68564855 | D26: =('Balance Sheet'!D33-'Balance Sheet'!D7)/('Income Statement'!D23+Assumptions!D24) -> 0.96395349 | E26: =('Balance Sheet'!E33-'Balance Sheet'!E7)/('Income Statement'!E23+Assumptions!E24) -> 0.52795261 | F26: =('Balance Sheet'!F33-'Balance Sheet'!F7)/('Income Statement'!F23+Assumptions!F24) -> 0.48817006 | G26: =('Balance Sheet'!G33-'Balance Sheet'!G7)/('Income Statement'!G23+Assumptions!G24) -> 0.094175372 | H26: =('Balance Sheet'!H33-'Balance Sheet'!H7)/('Income Statement'!H23+Assumptions!H24) -> 0.46108643 | I26: =('Balance Sheet'!I33-'Balance Sheet'!I7)/('Income Statement'!I23+Assumptions!I24) -> 0.26591658 | J26: =('Balance Sheet'!J33-'Balance Sheet'!J7)/('Income Statement'!J23+Assumptions!J24) -> 0.30951077 | ... L26: =('Balance Sheet'!L33-'Balance Sheet'!L7)/('Income Statement'!L23+Assumptions!L24) -> -0.053988954 | M26: (LT Debt - Cash) / EBITDA
B27: Interest Coverage | C27: ='Income Statement'!C23/ABS('Income Statement'!C29) -> 11.397436 | D27: ='Income Statement'!D23/ABS('Income Statement'!D29) -> 12.458333 | E27: ='Income Statement'!E23/ABS('Income Statement'!E29) -> 18.112069 | F27: ='Income Statement'!F23/ABS('Income Statement'!F29) -> 13.385113 | G27: ='Income Statement'!G23/ABS('Income Statement'!G29) -> 13.775342 | H27: ='Income Statement'!H23/ABS('Income Statement'!H29) -> 14.586735 | I27: ='Income Statement'!I23/ABS('Income Statement'!I29) -> 15.095477 | J27: ='Income Statement'!J23/ABS('Income Statement'!J29) -> 12.917927 | ... L27: ='Income Statement'!L23/ABS('Income Statement'!L29) -> 15.105714 | M27: EBIT / Interest Expense
B30: EFFICIENCY
B31: Asset Turnover | C31: ='Income Statement'!C7/'Balance Sheet'!C21 -> 0.34621004 | D31: ='Income Statement'!D7/'Balance Sheet'!D21 -> 0.30483525 | E31: ='Income Statement'!E7/'Balance Sheet'!E21 -> 0.33469652 | F31: ='Income Statement'!F7/'Balance Sheet'!F21 -> 0.34999491 | G31: ='Income Statement'!G7/'Balance Sheet'!G21 -> 0.36232748 | H31: ='Income Statement'!H7/'Balance Sheet'!H21 -> 0.40389965 | I31: ='Income Statement'!I7/'Balance Sheet'!I21 -> 0.41375525 | J31: ='Income Statement'!J7/'Balance Sheet'!J21 -> 0.42152591 | ... L31: ='Income Statement'!L7/'Balance Sheet'!L21 -> 0.43666773 | M31: Revenue / Total Assets
B32: CapEx / Revenue | C32: =ABS('Cash Flow'!C25)/'Income Statement'!C7 -> 0.039612874 | D32: =ABS('Cash Flow'!D25)/'Income Statement'!D7 -> 0.040365433 | E32: =ABS('Cash Flow'!E25)/'Income Statement'!E7 -> 0.035788893 | F32: =ABS('Cash Flow'!F25)/'Income Statement'!F7 -> 0.025655934 | G32: =ABS('Cash Flow'!G25)/'Income Statement'!G7 -> 0.020019482 | H32: =ABS('Cash Flow'!H25)/'Income Statement'!H7 -> 0.016227946 | I32: =ABS('Cash Flow'!I25)/'Income Statement'!I7 -> 0.015223683 | J32: =ABS('Cash Flow'!J25)/'Income Statement'!J7 -> 0.026338894 | ... L32: =ABS('Cash Flow'!L25)/'Income Statement'!L7 -> 0.021436227 | M32: Capital intensity
B35: GROWTH
B36: Revenue Growth (YoY) | D36: =('Income Statement'!D7-'Income Statement'!C7)/'Income Statement'!C7 -> 0.20717983 | E36: =('Income Statement'!E7-'Income Statement'!D7)/'Income Statement'!D7 -> 0.18257668 | F36: =('Income Statement'!F7-'Income Statement'!E7)/'Income Statement'!E7 -> 0.084624177 | G36: =('Income Statement'!G7-'Income Statement'!F7)/'Income Statement'!F7 -> 0.081873683 | H36: =('Income Statement'!H7-'Income Statement'!G7)/'Income Statement'!G7 -> 0.068052803 | I36: =('Income Statement'!I7-'Income Statement'!H7)/'Income Statement'!H7 -> 0.043243073 | J36: =('Income Statement'!J7-'Income Statement'!I7)/'Income Statement'!I7 -> 0.030085614 | K36: =('Income Statement'!K7-'Income Statement'!J7)/'Income Statement'!J7 -> 0.040093649 | L36: =('Income Statement'!L7-'Income Statement'!K7)/'Income Statement'!K7 -> 0.050084412 | M36: YoY Revenue Growth
B37: Net Income Growth (YoY) | D37: =('Income Statement'!D39-'Income Statement'!C39)/ABS('Income Statement'!C39) -> 0.70882473 | E37: =('Income Statement'!E39-'Income Statement'!D39)/ABS('Income Statement'!D39) -> -0.0078534031 | F37: =('Income Statement'!F39-'Income Statement'!E39)/ABS('Income Statement'!E39) -> -0.41976493 | G37: =('Income Statement'!G39-'Income Statement'!F39)/ABS('Income Statement'!F39) -> 0.75527077 | H37: =('Income Statement'!H39-'Income Statement'!G39)/ABS('Income Statement'!G39) -> 0.07701366 | I37: =('Income Statement'!I39-'Income Statement'!H39)/ABS('Income Statement'!H39) -> -0.05751148 | J37: =('Income Statement'!J39-'Income Statement'!I39)/ABS('Income Statement'!I39) -> -0.022487239 | K37: =('Income Statement'!K39-'Income Statement'!J39)/ABS('Income Statement'!J39) -> 0.086714708 | L37: =('Income Statement'!L39-'Income Statement'!K39)/ABS('Income Statement'!K39) -> 0.092849579 | M37: YoY Net Income Growth
B38: EPS Growth (YoY) | D38: =('Income Statement'!D46-'Income Statement'!C46)/ABS('Income Statement'!C46) -> 0.71014493 | E38: =('Income Statement'!E46-'Income Statement'!D46)/ABS('Income Statement'!D46) -> -0.0056497175 | F38: =('Income Statement'!F46-'Income Statement'!E46)/ABS('Income Statement'!E46) -> -0.40625 | G38: =('Income Statement'!G46-'Income Statement'!F46)/ABS('Income Statement'!F46) -> 0.83732057 | H38: =('Income Statement'!H46-'Income Statement'!G46)/ABS('Income Statement'!G46) -> 0.13020833 | I38: =('Income Statement'!I46-'Income Statement'!H46)/ABS('Income Statement'!H46) -> 0.055299539 | J38: =('Income Statement'!J46-'Income Statement'!I46)/ABS('Income Statement'!I46) -> -0.02139738 | K38: =('Income Statement'!K46-'Income Statement'!J46)/ABS('Income Statement'!J46) -> 0.1477661 | L38: =('Income Statement'!L46-'Income Statement'!K46)/ABS('Income Statement'!K46) -> 0.15790015 | M38: YoY EPS Growth (key for investors)

Sheet DCF
B1: PayPal (PYPL) — DCF Valuation
B2: Discounted Cash Flow — Free Cash Flow to Firm (FCFF)
B4: WACC CALCULATION
B5: Risk-Free Rate (Rf) | C5: 0.042 | D5: 10Y UST yield
B6: Equity Risk Premium (ERP) | C6: 0.055 | D6: Damodaran 2025
B7: Beta (β) | C7: 1.4 | D7: Elevated: CEO change + competition
B8: Cost of Equity (Ke) | C8: =C5+C7*C6 -> 0.119 | D8: CAPM formula
B10: Pre-Tax Cost of Debt (Kd) | C10: 0.042 | D10: Int Exp / Avg Debt
B11: Tax Rate (t) | C11: 0.175 | D11: Effective tax rate
B12: After-Tax Cost of Debt | C12: =C10*(1-C11) -> 0.03465 | D12: Kd × (1 - t)
B14: Debt Weight (D/V) | C14: 0.3 | D14: Target capital structure
B15: Equity Weight (E/V) | C15: 0.7 | D15: 1 - Debt Weight
B17: WACC | C17: =C15*C8+C14*C10*(1-C11) -> 0.093695 | D17: THE discount rate
B20: FREE CASH FLOW PROJECTION
C21: 2026E | D21: 2027E | E21: 2028E | F21: Terminal
B22: Free Cash Flow ($M) | C22: ='Cash Flow'!J49 -> 5896.3586 | D22: ='Cash Flow'!K49 -> 6745.7488 | E22: ='Cash Flow'!L49 -> 7710.7653
B23: Terminal Growth Rate | C23: 0.015 | D23: Key assumption — sensitivity tested below
B24: Terminal Value ($M) | F24: =E22*(1+C23)/(C17-C23) -> 99452.656 | G24: FCF_2028 × (1+g) / (WACC-g)
B26: Discount Factor | C26: =1/(1+C17)^1 -> 0.91433169 | D26: =1/(1+C17)^2 -> 0.83600244 | E26: =1/(1+C17)^3 -> 0.76438353 | F26: =1/(1+C17)^3 -> 0.76438353
B27: PV of Free Cash Flow ($M) | C27: =C22*C26 -> 5391.2276 | D27: =D22*D26 -> 5639.4625 | E27: =E22*E26 -> 5893.982 | F27: =F24*F26 -> 76019.972
B29: EQUITY VALUE BRIDGE
B30: PV of Projected FCFs ($M) | C30: =SUM(C27:E27) -> 16924.672
B31: PV of Terminal Value ($M) | C31: =F27 -> 76019.972
B32: Enterprise Value ($M) | C32: =C30+C31 -> 92944.644
B33: Terminal Value as % of EV | C33: =C31/C32 -> 0.81790589 | D33: Should be 60-85% for mature company
B35: (−) Net Debt ($M) | C35: ='Balance Sheet'!I33-'Balance Sheet'!I7 -> 1938 | D35: LT Debt - Cash (latest actual: FY2025)
B36: Equity Value ($M) | C36: =C32-C35 -> 91006.644
B38: Diluted Shares Outstanding (M) | C38: ='Income Statement'!I45 -> 941 | D38: Latest actual (FY2025)
B39: Implied Share Price | C39: =C36/C38 -> 96.712693
B42: SENSITIVITY ANALYSIS — Implied Share Price
B43: WACC (rows) vs Terminal Growth Rate (columns)
B44: WACC \ TGR → | C44: =C23+-0.01 -> 0.005 | D44: =C23+-0.005 -> 0.01 | E44: =C23+0 -> 0.015 | F44: =C23+0.005 -> 0.02 | G44: =C23+0.01 -> 0.025
B45: =C17+-0.02 -> 0.073695 | C45: =(C22/(1+$B45)^1+D22/(1+$B45)^2+E22/(1+$B45)^3+E22*(1+C$44)/($B45-C$44)/(1+$B45)^3-C35)/C38 -> 113.46639 | D45: =(C22/(1+$B45)^1+D22/(1+$B45)^2+E22/(1+$B45)^3+E22*(1+D$44)/($B45-D$44)/(1+$B45)^3-C35)/C38 -> 121.58881 | E45: =(C22/(1+$B45)^1+D22/(1+$B45)^2+E22/(1+$B45)^3+E22*(1+E$44)/($B45-E$44)/(1+$B45)^3-C35)/C38 -> 131.09507 | F45: =(C22/(1+$B45)^1+D22/(1+$B45)^2+E22/(1+$B45)^3+E22*(1+F$44)/($B45-F$44)/(1+$B45)^3-C35)/C38 -> 142.37175 | G45: =(C22/(1+$B45)^1+D22/(1+$B45)^2+E22/(1+$B45)^3+E22*(1+G$44)/($B45-G$44)/(1+$B45)^3-C35)/C38 -> 155.9642
B46: =C17+-0.01 -> 0.083695 | C46: =(C22/(1+$B46)^1+D22/(1+$B46)^2+E22/(1+$B46)^3+E22*(1+C$44)/($B46-C$44)/(1+$B46)^3-C35)/C38 -> 98.490626 | D46: =(C22/(1+$B46)^1+D22/(1+$B46)^2+E22/(1+$B46)^3+E22*(1+D$44)/($B46-D$44)/(1+$B46)^3-C35)/C38 -> 104.50622 | E46: =(C22/(1+$B46)^1+D22/(1+$B46)^2+E22/(1+$B46)^3+E22*(1+E$44)/($B46-E$44)/(1+$B46)^3-C35)/C38 -> 111.39751 | F46: =(C22/(1+$B46)^1+D22/(1+$B46)^2+E22/(1+$B46)^3+E22*(1+F$44)/($B46-F$44)/(1+$B46)^3-C35)/C38 -> 119.37072 | G46: =(C22/(1+$B46)^1+D22/(1+$B46)^2+E22/(1+$B46)^3+E22*(1+G$44)/($B46-G$44)/(1+$B46)^3-C35)/C38 -> 128.70235
B47: =C17+-0.005 -> 0.088695 | C47: =(C22/(1+$B47)^1+D22/(1+$B47)^2+E22/(1+$B47)^3+E22*(1+C$44)/($B47-C$44)/(1+$B47)^3-C35)/C38 -> 92.347295 | D47: =(C22/(1+$B47)^1+D22/(1+$B47)^2+E22/(1+$B47)^3+E22*(1+D$44)/($B47-D$44)/(1+$B47)^3-C35)/C38 -> 97.595596 | E47: =(C22/(1+$B47)^1+D22/(1+$B47)^2+E22/(1+$B47)^3+E22*(1+E$44)/($B47-E$44)/(1+$B47)^3-C35)/C38 -> 103.55606 | F47: =(C22/(1+$B47)^1+D22/(1+$B47)^2+E22/(1+$B47)^3+E22*(1+F$44)/($B47-F$44)/(1+$B47)^3-C35)/C38 -> 110.3842 | G47: =(C22/(1+$B47)^1+D22/(1+$B47)^2+E22/(1+$B47)^3+E22*(1+G$44)/($B47-G$44)/(1+$B47)^3-C35)/C38 -> 118.28434
B48: =C17+0 -> 0.093695 | C48: =(C22/(1+$B48)^1+D22/(1+$B48)^2+E22/(1+$B48)^3+E22*(1+C$44)/($B48-C$44)/(1+$B48)^3-C35)/C38 -> 86.898171 | D48: =(C22/(1+$B48)^1+D22/(1+$B48)^2+E22/(1+$B48)^3+E22*(1+D$44)/($B48-D$44)/(1+$B48)^3-C35)/C38 -> 91.512269 | E48: =(C22/(1+$B48)^1+D22/(1+$B48)^2+E22/(1+$B48)^3+E22*(1+E$44)/($B48-E$44)/(1+$B48)^3-C35)/C38 -> 96.712693 | F48: =(C22/(1+$B48)^1+D22/(1+$B48)^2+E22/(1+$B48)^3+E22*(1+F$44)/($B48-F$44)/(1+$B48)^3-C35)/C38 -> 102.61879 | G48: =(C22/(1+$B48)^1+D22/(1+$B48)^2+E22/(1+$B48)^3+E22*(1+G$44)/($B48-G$44)/(1+$B48)^3-C35)/C38 -> 109.38463
B49: =C17+0.005 -> 0.098695 | C49: =(C22/(1+$B49)^1+D22/(1+$B49)^2+E22/(1+$B49)^3+E22*(1+C$44)/($B49-C$44)/(1+$B49)^3-C35)/C38 -> 82.032092 | D49: =(C22/(1+$B49)^1+D22/(1+$B49)^2+E22/(1+$B49)^3+E22*(1+D$44)/($B49-D$44)/(1+$B49)^3-C35)/C38 -> 86.116301 | E49: =(C22/(1+$B49)^1+D22/(1+$B49)^2+E22/(1+$B49)^3+E22*(1+E$44)/($B49-E$44)/(1+$B49)^3-C35)/C38 -> 90.688498 | F49: =(C22/(1+$B49)^1+D22/(1+$B49)^2+E22/(1+$B49)^3+E22*(1+F$44)/($B49-F$44)/(1+$B49)^3-C35)/C38 -> 95.841697 | G49: =(C22/(1+$B49)^1+D22/(1+$B49)^2+E22/(1+$B49)^3+E22*(1+G$44)/($B49-G$44)/(1+$B49)^3-C35)/C38 -> 101.69416
B50: =C17+0.01 -> 0.103695 | C50: =(C22/(1+$B50)^1+D22/(1+$B50)^2+E22/(1+$B50)^3+E22*(1+C$44)/($B50-C$44)/(1+$B50)^3-C35)/C38 -> 77.660419 | D50: =(C22/(1+$B50)^1+D22/(1+$B50)^2+E22/(1+$B50)^3+E22*(1+D$44)/($B50-D$44)/(1+$B50)^3-C35)/C38 -> 81.297627 | E50: =(C22/(1+$B50)^1+D22/(1+$B50)^2+E22/(1+$B50)^3+E22*(1+E$44)/($B50-E$44)/(1+$B50)^3-C35)/C38 -> 85.344916 | F50: =(C22/(1+$B50)^1+D22/(1+$B50)^2+E22/(1+$B50)^3+E22*(1+F$44)/($B50-F$44)/(1+$B50)^3-C35)/C38 -> 89.87578 | G50: =(C22/(1+$B50)^1+D22/(1+$B50)^2+E22/(1+$B50)^3+E22*(1+G$44)/($B50-G$44)/(1+$B50)^3-C35)/C38 -> 94.982395
B51: =C17+0.02 -> 0.113695 | C51: =(C22/(1+$B51)^1+D22/(1+$B51)^2+E22/(1+$B51)^3+E22*(1+C$44)/($B51-C$44)/(1+$B51)^3-C35)/C38 -> 70.127299 | D51: =(C22/(1+$B51)^1+D22/(1+$B51)^2+E22/(1+$B51)^3+E22*(1+D$44)/($B51-D$44)/(1+$B51)^3-C35)/C38 -> 73.058043 | E51: =(C22/(1+$B51)^1+D22/(1+$B51)^2+E22/(1+$B51)^3+E22*(1+E$44)/($B51-E$44)/(1+$B51)^3-C35)/C38 -> 76.285737 | F51: =(C22/(1+$B51)^1+D22/(1+$B51)^2+E22/(1+$B51)^3+E22*(1+F$44)/($B51-F$44)/(1+$B51)^3-C35)/C38 -> 79.857921 | G51: =(C22/(1+$B51)^1+D22/(1+$B51)^2+E22/(1+$B51)^3+E22*(1+G$44)/($B51-G$44)/(1+$B51)^3-C35)/C38 -> 83.832853
B53: Yellow cell = base case (matches implied share price above)
...

Sheet Scenarios
B1: PayPal (PYPL) — Scenario Analysis
B2: Three scenarios with probability-weighted target price
C4: Bull Case | D4: Base Case | E4: Bear Case
B5: Narrative | C5: New CEO executes turnaround; branded checkout recovers; Venmo monetization accelerates | D5: Modest growth continues; branded checkout stabilizes; cost discipline maintained | E5: Branded checkout declines; Apple/Google take share; margin compression from competition
B7: KEY ASSUMPTIONS (FY2028E)
B8: Revenue Growth '26-'28 Avg | C8: 6.0% | D8: 4.0% | E8: 1.5%
B9: FY2028E Revenue ($M) | C9: 38500 | D9: 37320 | E9: 34800
B10: Operating Margin '28E | C10: 22.0% | D10: 19.5% | E10: 15.5%
B11: FY2028E Net Income ($M) | C11: 6200 | D11: 4800 | E11: 3200
B12: FY2028E FCF ($M) | C12: 8500 | D12: (from model) | E12: 3500
B13: CapEx ($M/yr avg) | C13: 700 | D13: 850 | E13: 950
B14: Terminal Growth Rate | C14: 2.5% | D14: 1.5% | E14: 1.0%
B15: WACC | C15: 8.5% | D15: 9.9% | E15: 11.5%
B17: VALUATION OUTPUT
B18: FY2028E Free Cash Flow ($M) | C18: 8500 | D18: ='Cash Flow'!L49 -> 7710.7653 | E18: 3500
B19: Terminal Value ($M) | C19: =C18*(1+0.025)/(0.085-0.025) -> 145208.33 | D19: =D18*(1+0.015)/(0.099-0.015) -> 93171.747 | E19: =E18*(1+0.01)/(0.115-0.01) -> 33666.667
B20: PV of Terminal Value ($M) | C20: =C19/(1+0.085)^3 -> 113684.78 | D20: =D19/(1+0.099)^3 -> 70192.573 | E20: =E19/(1+0.115)^3 -> 24287.092
B21: PV of Projected FCFs ($M) | C21: =6500/(1+0.085)^1+7500/(1+0.085)^2+C18/(1+0.085)^3 -> 19016.417 | D21: ='Cash Flow'!J49/(1+0.099)^1+'Cash Flow'!K49/(1+0.099)^2+'Cash Flow'!L49/(1+0.099)^3 -> 16759.393 | E21: =2500/(1+0.115)^1+3000/(1+0.115)^2+E18/(1+0.115)^3 -> 7180.1271
B22: Enterprise Value ($M) | C22: =C21+C20 -> 132701.2 | D22: =D21+D20 -> 86951.966 | E22: =E21+E20 -> 31467.219
B23: (-) Net Debt ($M) | C23: =DCF!C35 -> 1938 | D23: =DCF!C35 -> 1938 | E23: =DCF!C35 -> 1938
B24: Equity Value ($M) | C24: =C22-C23 -> 130763.2 | D24: =D22-D23 -> 85013.966 | E24: =E22-E23 -> 29529.219
B25: Diluted Shares (M) | C25: =DCF!C38 -> 941 | D25: =DCF!C38 -> 941 | E25: =DCF!C38 -> 941
B27: IMPLIED SHARE PRICE PER SCENARIO
B28: Implied Share Price | C28: =C24/C25 -> 138.96195 | D28: =D24/D25 -> 90.344278 | E28: =E24/E25 -> 31.380679
B30: PROBABILITY-WEIGHTED TARGET PRICE
B31: Probability Weight | C31: 0.15 | D31: 0.35 | E31: 0.5
B32: Sum (must = 100%) | C32: =C31+D31+E31 -> 1
B33: Weighted Contribution | C33: =C28*C31 -> 20.844293 | D33: =D28*D31 -> 31.620497 | E33: =E28*E31 -> 15.69034
B35: TARGET PRICE | C35: =C33+D33+E33 -> 68.15513
B37: Current Market Price | C37: 40.42 | D37: As of Feb 9, 2026 (editable)
B38: Implied Upside / (Downside) | C38: =(C35/C37)-1 -> 0.68617342
B40: RECOMMENDATION
B41: Rating | C41: =IF(C38>0.2,"BUY",IF(C38>-0.1,"HOLD","SELL")) -> BUY
B42: Decision Rule: | C42: Upside > 20% = BUY | > -10% = HOLD | else SELL
B44: VALUATION RANGE (Football Field)
B45: Metric | C45: Price
B46: Bear Case DCF | C46: =E28 -> 31.380679
B47: Current Market Price | C47: =C37 -> 40.42
B48: Analyst Consensus (avg) | C48: 62.46
B49: Probability-Weighted Target | C49: =C35 -> 68.15513
...

Sheet Investment Memo
B1: INVESTMENT MEMO — PayPal Holdings, Inc. (NASDAQ: PYPL)
B2: Equity Research | February 2026 | Analyst: Carlos
B4: EXECUTIVE SUMMARY
B5: PayPal Holdings, Inc. is the world's largest digital payments platform, processing $1.8 trillion in TPV across ~200 markets in FY2025. The company is at an inflection point: Q4 2025 results missed expectations, the board replaced CEO Alex Chriss with HP's Enrique Lores, and 2026 guidance disappointed with flat-to-declining EPS projections. The stock has fallen ~50% from its 52-week high to ~$40.
B7: Despite near-term headwinds, PayPal generates strong free cash flow (~$7B annually), maintains a disciplined $6B/year buyback program, and owns valuable network effects across 438M active accounts. Venmo revenue grew 20% to $1.7B and BNPL TPV surpassed $40B. The question is whether the new CEO can stabilize branded checkout and fend off Apple Pay/Google Pay competition.
B9: KEY FINANCIAL HIGHLIGHTS (FY2025 Actual)
B10: Revenue: $33.2B (+4% YoY) | Operating Income: $6.0B (18.1% margin) | Net Income: $4.3B | EPS: $4.58
B11: Free Cash Flow: $6.6B (19.9% FCF margin) | Cash: $8.0B | LT Debt: $10.0B | Net Debt: $1.9B
B12: Shares outstanding declined from 1,188M (2019) to 941M (2025) via aggressive buybacks — 21% reduction in 6 years
B14: INVESTMENT THESIS
B15: The bull case rests on four pillars:
B16: 1. Valuation gap: Trading at ~8x trailing FCF, PayPal is priced like a declining business while still growing revenue 4%/year and generating world-class cash flow.
... B37: RECOMMENDATION
B39: =IF(Scenarios!C38>0.2,"RECOMMENDATION: BUY — Target Price: "&TEXT(Scenarios!C35,"$#,##0.00")&" | Current: "&TEXT(Scenarios!C37,"$#,##0.00")&" | Upside: "&TEXT(Scenarios!C38,"0.0%"),IF(Scenarios!C38>-0.1,"RECOMMENDATION: HOLD — Target Price: "&TEXT(Scenarios!C35,"$#,##0.00")&" | Current: "&TEXT(Scenarios!C37,"$#,##0.00")&" | Upside: "&TEXT(Scenarios!C38,"0.0%"),"RECOMMENDATION: SELL — Target Price: "&TEXT(Scenarios!C35,"$#,##0.00")&" | Current: "&TEXT(Scenarios!C37,"$#,##0.00")&" | Downside: "&TEXT(Scenarios!C38,"0.0%"))) -> RECOMMENDATION: BUY — Target Price: $68,15513 | Current: $40,42000 | Upside: 69%
B41: PayPal represents a contrarian value opportunity with significant margin of safety. The stock is priced for permanent decline, yet the company generates best-in-class FCF, is aggressively reducing shares outstanding, and has multiple levers for revenue diversification (Venmo, BNPL, enterprise payments, agentic commerce). The primary risk is execution under new leadership.
B43: This is NOT a high-conviction BUY given the CEO transition uncertainty. Position sizing should reflect the wide range of outcomes shown in the scenario analysis. The thesis requires monitoring branded checkout trends and Lores's strategic direction over the next 2-3 quarters.
B45: CATALYST TIMELINE
B46: March 1, 2026: Enrique Lores officially starts as CEO
B47: May 2026: Q1 2026 earnings — first report under new leadership direction
B48: H2 2026: Expected strategic review / new Investor Day under Lores
B49: 2027: Full year under new CEO — execution proof point
B51: METHODOLOGY & SOURCES
B52: Financial data: SEC EDGAR 10-K filings (FY2019-2025), yfinance API, PayPal Q4 2025 earnings release (Feb 3, 2026)
B53: Model: 3-statement financial model (IS/BS/CF fully linked) with 3-year forecast (FY2026E-2028E)
B54: Valuation: Discounted Cash Flow (FCFF), Gordon Growth terminal value, WACC via CAPM
B55: Scenario analysis: Bull/Base/Bear with probability-weighted target price
... B59: This analysis is prepared for educational and portfolio demonstration purposes only. It does not constitute investment advice. The author has no position in PYPL and does not intend to initiate one within 72 hours of this publication. All projections are forward-looking estimates subject to significant uncertainty.
